<?xml version='1.0'?>
<sdf version='1.6'>
  <model name='skywalker'>
    <!-- Note: Unlike standard aero NED systems, this makes use of the ROS ENU standard with mapping taking place externally -->
    <pose>0 0 0 0 0 0</pose>
    <static>false</static>
    <link name='x8_body'>
      <pose>0 0 0.11 0 0 0</pose>
      <inertial>
        <pose>0 0 0 0 0 0</pose> <!-- Body origin defined at CG -->
        <mass>3.364</mass>
        <inertia> <!-- Note that X and Y are swapped from NED coordinate version -->
          <ixx>0.1702</ixx>
          <ixy>0</ixy>
          <ixz>0</ixz>
          <iyy>1.229</iyy>
          <iyz>0.9343</iyz>
          <izz>0.8808</izz>
        </inertia>
      </inertial>
      <collision name='x8_body_collision'>
        <pose>0 0 0.045 0 0 1.5708</pose>
        <geometry>
          <box>
            <size>0.931 2.151 0.31</size>
          </box>
        </geometry>
        <surface>
          <contact>
            <ode>
              <max_vel>10</max_vel>
              <min_depth>0.01</min_depth>
            </ode>
          </contact>
        </surface>
      </collision>
      <visual name='x8_body_visual'>
        <pose>0 0 0 0 0 0</pose>
        <geometry>
          <mesh>
            <scale>1 1 1</scale>
            <uri>model://skywalker/meshes/x8_body.dae</uri>
          </mesh>
        </geometry>
      </visual>
    </link>

    <link name='x8_propeller'>
      <pose>0 -0.34687 0.11 0 0 0</pose>
      <inertial>
        <pose>0 0 0 0 0 0</pose>
        <mass>0.005</mass>
        <inertia>
          <ixx>9.75e-07</ixx>
          <ixy>0</ixy>
          <ixz>0</ixz>
          <iyy>0.000166704</iyy>
          <iyz>0</iyz>
          <izz>0.000167604</izz>
        </inertia>
      </inertial>
      <collision name='x8_propeller_collision'>
        <pose>0 0 0 1.5707963 0 0</pose>
        <geometry>
          <cylinder>
            <length>0.01031</length>
            <radius>0.13</radius>
          </cylinder>
        </geometry>
        <surface>
          <contact>
            <ode/>
          </contact>
          <friction>
            <ode/>
          </friction>
        </surface>
      </collision>
      <visual name='x8_propeller_visual'>
        <pose>0 0 0 0 0 0</pose>
        <geometry>
          <mesh>
            <scale>1 1 1</scale>
            <uri>model://skywalker/meshes/x8_propeller.dae</uri>
          </mesh>
        </geometry>
      </visual>
      <gravity>1</gravity>
      <velocity_decay/>
      <self_collide>0</self_collide>
    </link>
    <joint name='x8_propeller_joint' type='revolute'>
      <parent>x8_body</parent>
      <child>x8_propeller</child>
      <pose>0 0 0 0 0 0</pose>
      <axis>
        <xyz>0 1 0</xyz>
        <dynamics>
          <damping>1</damping>
        </dynamics>
        <use_parent_model_frame>true</use_parent_model_frame>
      </axis>
      <physics>
        <ode>
          <implicit_spring_damper>true</implicit_spring_damper>
        </ode>
      </physics>
    </joint>

    <link name="left_elevon">
      <pose>-0.75116 -0.35502 0.10633 0 0 0</pose>
      <inertial>
        <pose>0 0 0 0 0 0</pose>
        <mass>0.001</mass>
        <inertia>
          <ixx>0.00001</ixx>
          <ixy>0.0</ixy>
          <iyy>0.00001</iyy>
          <ixz>0.0</ixz>
          <iyz>0.0</iyz>
          <izz>0.00001</izz>
        </inertia>
      </inertial>
      <visual name='left_elevon_visual'>
        <pose>0 0 0 0 0 0</pose>
        <geometry>
          <mesh>
            <scale>1 1 1</scale>
            <uri>model://skywalker/meshes/x8_elevon_left.dae</uri>
          </mesh>
        </geometry>
      </visual>
    </link>
    <joint name='left_elevon_joint' type='revolute'>
      <parent>x8_body</parent>
      <child>left_elevon</child>
      <pose>0 0.042273 0 0 0 0.26529</pose>
      <axis>
        <xyz>1 0 0</xyz>
        <limit>
          <!-- -15/+15 deg. -->
          <lower>-0.2618</lower>
          <upper>0.2618</upper>
        </limit>
        <dynamics>
          <damping>1.000</damping>
        </dynamics>
      </axis>
      <physics>
        <ode>
          <implicit_spring_damper>true</implicit_spring_damper>
        </ode>
      </physics>
    </joint>

    <link name="right_elevon">
      <pose>0.75116 -0.35502 0.10633 0 0 0</pose>
      <inertial>
        <pose>0 0 0 0 0 0</pose>
        <mass>0.001</mass>
        <inertia>
          <ixx>0.00001</ixx>
          <ixy>0.0</ixy>
          <iyy>0.00001</iyy>
          <ixz>0.0</ixz>
          <iyz>0.0</iyz>
          <izz>0.00001</izz>
        </inertia>
      </inertial>
      <visual name='right_elevon_visual'>
        <pose>0 0 0 0 0 0</pose>
        <geometry>
          <mesh>
            <scale>1 1 1</scale>
            <uri>model://skywalker/meshes/x8_elevon_right.dae</uri>
          </mesh>
        </geometry>
      </visual>
    </link>
    <joint name='right_elevon_joint' type='revolute'>
      <parent>x8_body</parent>
      <child>right_elevon</child>
      <pose>0 0.042273 0 0 0 -0.26529</pose>
      <axis>
        <xyz>1 0 0</xyz>
        <limit>
          <!-- -15/+15 deg. -->
          <lower>-0.2618</lower>
          <upper>0.2618</upper>
        </limit>
        <dynamics>
          <damping>1.000</damping>
        </dynamics>
      </axis>
      <physics>
        <ode>
          <implicit_spring_damper>true</implicit_spring_damper>
        </ode>
      </physics>
    </joint>

    <plugin name='vehicle_Aerodynamics' filename='libvehicle_aerodynamics.so'>
	<link_name>x8_body</link_name>
	<vehicle_config>FlyingWing</vehicle_config>
	<controlJoint_portElevon>left_elevon_joint</controlJoint_portElevon>
	<controlJoint_starboardElevon>right_elevon_joint</controlJoint_starboardElevon>
	<CL0>0.0867</CL0>
	<CLalpha>4.02</CLalpha>
	<CLq>3.8954</CLq>
	<CLde>0.278</CLde>
	<CD0>0.0197</CD0>
	<CDalpha>0.0791</CDalpha>
	<CDalpha2>1.06</CDalpha2>
	<CDq>0.0</CDq>
	<CDbeta2>0.148</CDbeta2>
	<CDbeta>-0.00584</CDbeta>
	<CDde>0.0633</CDde>
	<CY0>0.0</CY0>
	<CYbeta>-0.224</CYbeta>
	<CYp>-0.1172</CYp>
	<CYr>0.0959</CYr>
	<CYda>0.0433</CYda>
	<Cl0>0.0</Cl0>
	<Clbeta>-0.0849</Clbeta>
	<Clp>-0.4018</Clp>
	<Clr>0.025</Clr>
	<Clda>0.12</Clda>
	<Cldr>0.0</Cldr>
	<Cm0>0.0302</Cm0>
	<Cmalpha>-0.126</Cmalpha>
	<Cmq>-1.3047</Cmq>
	<Cmde>-0.206</Cmde>
	<Cn0>0.0</Cn0>
	<Cnbeta>0.0283</Cnbeta>
	<Cnp>-0.0247</Cnp>
	<Cnr>-0.1252</Cnr>
	<Cnda>-0.00339</Cnda>
	<Cndr>0.0</Cndr>
	<b>2.1</b>
	<c>0.3571</c>
	<S>0.75</S>
	<alpha_0>0.267</alpha_0>
	<M_trans>50.0</M_trans>
	<C_mfp>-0.2168</C_mfp>
    </plugin>
    <plugin name='propeller_aerodynamics' filename='libpropeller_aerodynamics.so'>
	<link_name>x8_body</link_name>
	<propeller_joint>x8_propeller_joint</propeller_joint>
	<Sprop>0.1018</Sprop>
	<Cprop>0.5</Cprop>
	<kmotor>40</kmotor>
	<kT_p>0.0</kT_p>
	<komega>0.0</komega>
	<rotor_velocity_slowdown_sim>5</rotor_velocity_slowdown_sim>
	<rotation_direction>1</rotation_direction>
    </plugin>
  </model>
</sdf>
